I'm sorry, but an uncaught exception occurred.

While running game code:
  File "game/script.rpy", line 120, in script
    startup "Simple. Users would input relevant details about their desired alibi—time, location, circumstances—and AlibiAI's advanced algorithms would generate a meticulously crafted narrative, backed by seemingly authentic evidence."
Exception: Sayer 'startup' is not defined.

-- Full Traceback ------------------------------------------------------------

Full traceback:
  File "game/script.rpy", line 120, in script
    startup "Simple. Users would input relevant details about their desired alibi—time, location, circumstances—and AlibiAI's advanced algorithms would generate a meticulously crafted narrative, backed by seemingly authentic evidence."
  File "/Users/raagaviragothaman/Desktop/renpy-8.1.0-sdk/renpy/ast.py", line 890, in execute
    who = eval_who(self.who, self.who_fast)
  File "/Users/raagaviragothaman/Desktop/renpy-8.1.0-sdk/renpy/ast.py", line 783, in eval_who
    raise Exception("Sayer '%s' is not defined." % who)
Exception: Sayer 'startup' is not defined.

macOS-12.6-arm64-arm-64bit arm64
Ren'Py 8.1.0.23051307
CS247G 1.0
Mon May 15 17:10:52 2023
